<?xml version="1.0"?>
<robot xmlns:xacro="http://www.ros.org/wiki/xacro">

<!-- 
This is modified version of the KINOVA GEN3 7DoF to be parametrized as a xacro macro 
Original here: https://github.com/Kinovarobotics/ros_kortex/blob/kinetic-devel/kortex_description/arms/gen3/7dof/urdf/GEN3_URDF_V12.urdf
-->
<xacro:macro name="GEN3_URDF_V12"
             params="prefix parent">
    <link name="${prefix}Shoulder_Link">
      <inertial>
        <origin xyz="-2.3E-05 -0.010364 -0.07336" rpy="0 0 0" />
        <mass value="1.3773" />
        <inertia ixx="0.00457" ixy="1E-06" ixz="2E-06" iyy="0.004831" iyz="0.000448" izz="0.001409" />
      </inertial>
      <visual>
        <origin xyz="0 0 0" rpy="0 0 0" />
        <geometry>
          <mesh filename="package://p3bot_description/meshes/arms/shoulder_link.STL" />
        </geometry>
        <material name="">
          <color rgba="0.75294 0.75294 0.75294 1" />
        </material>
      </visual>
      <collision>
        <origin xyz="0 0 0" rpy="0 0 0" />
        <geometry>
          <mesh filename="package://p3bot_description/meshes/arms/shoulder_link.STL" />
        </geometry>
      </collision>
    </link>
    <joint name="${prefix}Actuator1" type="continuous">
      <parent link="${parent}" />
      <child link="${prefix}Shoulder_Link" />
      <axis xyz="0 0 1" />
      <limit effort="39" velocity="0.8727" />
    </joint>
    <link name="${prefix}HalfArm1_Link">
      <inertial>
        <origin xyz="-4.4E-05 -0.09958 -0.013278" rpy="0 0 0" />
        <mass value="1.1636" />
        <inertia ixx="0.011088" ixy="5E-06" ixz="0" iyy="0.001072" iyz="-0.000691" izz="0.011255" />
      </inertial>
      <visual>
        <origin xyz="0 0 0" rpy="0 0 0" />
        <geometry>
          <mesh filename="package://p3bot_description/meshes/arms/half_arm_1_link.STL" />
        </geometry>
        <material name="">
          <color rgba="0.75294 0.75294 0.75294 1" />
        </material>
      </visual>
      <collision>
        <origin xyz="0 0 0" rpy="0 0 0" />
        <geometry>
          <mesh filename="package://p3bot_description/meshes/arms/half_arm_1_link.STL" />
        </geometry>
      </collision>
    </link>
    <joint name="${prefix}Actuator2" type="revolute">
      <origin xyz="0 0.005375 -0.12838" rpy="1.5708 2.1343E-17 -1.1102E-16" />
      <parent link="${prefix}Shoulder_Link" />
      <child link="${prefix}HalfArm1_Link" />
      <axis xyz="0 0 1" />
      <limit lower="-2.41" upper="2.41" effort="39" velocity="0.8727" />
    </joint>
    <link name="${prefix}HalfArm2_Link">
      <inertial>
        <origin xyz="-4.4E-05 -0.006641 -0.117892" rpy="0 0 0" />
        <mass value="1.1636" />
        <inertia ixx="0.010932" ixy="0" ixz="-7E-06" iyy="0.011127" iyz="0.000606" izz="0.001043" />
      </inertial>
      <visual>
        <origin xyz="0 0 0" rpy="0 0 0" />
        <geometry>
          <mesh filename="package://p3bot_description/meshes/arms/half_arm_2_link.STL" />
        </geometry>
        <material name="">
          <color rgba="0.75294 0.75294 0.75294 1" />
        </material>
      </visual>
      <collision>
        <origin xyz="0 0 0" rpy="0 0 0" />
        <geometry>
          <mesh filename="package://p3bot_description/meshes/arms/half_arm_2_link.STL" />
        </geometry>
      </collision>
    </link>
    <joint name="${prefix}Actuator3" type="continuous">
      <origin xyz="0 -0.21038 -0.006375" rpy="-1.5708 1.2326E-32 -2.9122E-16" />
      <parent link="${prefix}HalfArm1_Link" />
      <child link="${prefix}HalfArm2_Link" />
      <axis xyz="0 0 1" />
      <limit effort="39" velocity="0.8727" />
    </joint>
    <link name="${prefix}ForeArm_Link">
      <inertial>
        <origin xyz="-1.8E-05 -0.075478 -0.015006" rpy="0 0 0" />
        <mass value="0.9302" />
        <inertia ixx="0.008147" ixy="-1E-06" ixz="0" iyy="0.000631" iyz="-0.0005" izz="0.008316" />
      </inertial>
      <visual>
        <origin xyz="0 0 0" rpy="0 0 0" />
        <geometry>
          <mesh filename="package://p3bot_description/meshes/arms/forearm_link.STL" />
        </geometry>
        <material name="">
          <color rgba="0.75294 0.75294 0.75294 1" />
        </material>
      </visual>
      <collision>
        <origin xyz="0 0 0" rpy="0 0 0" />
        <geometry>
          <mesh filename="package://p3bot_description/meshes/arms/forearm_link.STL" />
        </geometry>
      </collision>
    </link>
    <joint name="${prefix}Actuator4" type="revolute">
      <origin xyz="0 0.006375 -0.21038" rpy="1.5708 -6.6954E-17 -1.6653E-16" />
      <parent link="${prefix}HalfArm2_Link" />
      <child link="${prefix}ForeArm_Link" />
      <axis xyz="0 0 1" />
      <limit lower="-2.66" upper="2.66" effort="39" velocity="0.8727" />
    </joint>
    <link name="${prefix}SphericalWrist1_Link">
      <inertial>
        <origin xyz="1E-06 -0.009432 -0.063883" rpy="0 0 0" />
        <mass value="0.6781" />
        <inertia ixx="0.001596" ixy="0" ixz="0" iyy="0.001607" iyz="0.000256" izz="0.000399" />
      </inertial>
      <visual>
        <origin xyz="0 0 0" rpy="0 0 0" />
        <geometry>
          <mesh filename="package://p3bot_description/meshes/arms/spherical_wrist_1_link.STL" />
        </geometry>
        <material name="">
          <color rgba="0.75294 0.75294 0.75294 1" />
        </material>
      </visual>
      <collision>
        <origin xyz="0 0 0" rpy="0 0 0" />
        <geometry>
          <mesh filename="package://p3bot_description/meshes/arms/spherical_wrist_1_link.STL" />
        </geometry>
      </collision>
    </link>
    <joint name="${prefix}Actuator5" type="continuous">
      <origin xyz="0 -0.20843 -0.006375" rpy="-1.5708 2.2204E-16 -6.373E-17" />
      <parent link="${prefix}ForeArm_Link" />
      <child link="${prefix}SphericalWrist1_Link" />
      <axis xyz="0 0 1" />
      <limit effort="9" velocity="0.8727" />
    </joint>
    <link name="${prefix}SphericalWrist2_Link">
      <inertial>
        <origin xyz="1E-06 -0.045483 -0.00965" rpy="0 0 0" />
        <mass value="0.6781" />
        <inertia ixx="0.001641" ixy="0" ixz="0" iyy="0.00041" iyz="-0.000278" izz="0.001641" />
      </inertial>
      <visual>
        <origin xyz="0 0 0" rpy="0 0 0" />
        <geometry>
          <mesh filename="package://p3bot_description/meshes/arms/spherical_wrist_2_link.STL" />
        </geometry>
        <material name="">
          <color rgba="0.75294 0.75294 0.75294 1" />
        </material>
      </visual>
      <collision>
        <origin xyz="0 0 0" rpy="0 0 0" />
        <geometry>
          <mesh filename="package://p3bot_description/meshes/arms/spherical_wrist_2_link.STL" />
        </geometry>
      </collision>
    </link>
    <joint name="${prefix}Actuator6" type="revolute">
      <origin xyz="0 0.00017505 -0.10593" rpy="1.5708 9.2076E-28 -8.2157E-15" />
      <parent link="${prefix}SphericalWrist1_Link" />
      <child link="${prefix}SphericalWrist2_Link" />
      <axis xyz="0 0 1" />
      <limit lower="-2.23" upper="2.23" effort="9" velocity="0.8727" />
    </joint>
    <link name="${prefix}Bracelet_Link">
      <inertial>
        <origin xyz="-0.000281 -0.011402 -0.029798" rpy="0 0 0" />
        <mass value="0.5006" />
        <inertia ixx="0.000587" ixy="3E-06" ixz="3E-06" iyy="0.000369" iyz="0.000118" izz="0.000609" />
      </inertial>
      <visual>
        <origin xyz="0 0 0" rpy="0 0 0" />
        <geometry>
          <mesh filename="package://p3bot_description/meshes/arms/bracelet_no_vision_link.STL" />
        </geometry>
        <material name="">
          <color rgba="0.75294 0.75294 0.75294 1" />
        </material>
      </visual>
      <collision>
        <origin xyz="0 0 0" rpy="0 0 0" />
        <geometry>
          <mesh filename="package://p3bot_description/meshes/arms/bracelet_no_vision_link.STL" />
        </geometry>
      </collision>
    </link>
    <joint name="${prefix}Actuator7" type="continuous">
      <origin xyz="0 -0.10593 -0.00017505" rpy="-1.5708 -5.5511E-17 9.6396E-17" />
      <parent link="${prefix}SphericalWrist2_Link" />
      <child link="${prefix}Bracelet_Link" />
      <axis xyz="0 0 1" />
      <limit effort="9" velocity="0.8727" />
    </joint>
    <link name="${prefix}EndEffector_Link" />
    <joint name="${prefix}EndEffector" type="fixed">
      <origin xyz="0 0 -0.0615250000000001" rpy="3.14159265358979 1.09937075168372E-32 0" />
      <parent link="${prefix}Bracelet_Link" />
      <child link="${prefix}EndEffector_Link" />
      <axis xyz="0 0 0" />
    </joint>

  </xacro:macro>

</robot>
