<?xml version="1.0"?>
<robot xmlns:xacro="http://www.ros.org/wiki/xacro">

  <xacro:macro name="wheel" params="name parent xyz">

    <link name="${name}_link">
      <visual>
        <geometry>
          <cylinder radius="0.08" length="0.04"/>
        </geometry>
        <origin rpy="1.5708 0 0"/>
      </visual>

      <collision>
        <geometry>
          <cylinder radius="0.08" length="0.04"/>
        </geometry>
        <origin rpy="1.5708 0 0"/>
      </collision>

      <inertial>
        <mass value="2.0"/>
        <inertia ixx="0.01" iyy="0.01" izz="0.005"
                ixy="0" ixz="0" iyz="0"/>
      </inertial>
    </link>

    <joint name="${name}_joint" type="continuous">
      <parent link="${parent}"/>
      <child link="${name}_link"/>
      <origin xyz="${xyz}" rpy="0 0 0"/>
      <axis xyz="0 1 0"/>
    </joint>

  </xacro:macro>

  <xacro:macro name="p3bot_wheels" params="parent">
    <xacro:wheel name="front_left_wheel"  parent="${parent}" xyz="0.125  0.24 0.08"/>
    <xacro:wheel name="rear_left_wheel"   parent="${parent}" xyz="-0.125 0.24 0.08"/>
    <xacro:wheel name="front_right_wheel" parent="${parent}" xyz="0.125 -0.24 0.08"/>
    <xacro:wheel name="rear_right_wheel"  parent="${parent}" xyz="-0.125 -0.24 0.08"/>
  </xacro:macro>

</robot>